# 20230419

1. Nest.js unit test 작성 시 exception 발생 테스트하기

- nestjs에서 unit test를 작성하던 중 특정 상황에서 exception이 발생하는 것을 테스트하려고 함
- 처음에 작성했던 테스트 코드는 아래와 같음

  ```ts
  it("should check if the user is already registered", async () => {
    const newUserDto = {
      ...mockCreateUserDto,
      code: "000001",
      companyId: "1",
    } as CreateUserDto;

    const result = await controller.createUser(newUserDto);

    // 중복된 계정 코드가 있을 경우
    expect(result).rejects.toThrowError(ConflictException);

    expect(checkUserUsecaseProxy.byCode).toBeCalledWith(newUserDto.code, newUserDto.companyId);
  });
  ```

- 헌데 이렇게 하니 result 변수를 초기화하던 중 exception 발생으로 인해 테스트 진행이 되지 못하고 그대로 실패해버림
- exception 발생을 테스트하려는데, exception이 발생함으로 인해 테스트가 실패하는 요상한 상황이 발생함
- 어떻게 해야 하는가? 아래와 같이 함수 형태로 결과를 가져와서 expect에 넣어주면 되었음

  ```ts
  it("should check if the user is already registered", async () => {
    const newUserDto = {
      ...mockCreateUserDto,
      code: "000001",
      companyId: "1",
    } as CreateUserDto;

    // 중복된 계정 코드가 있는 경우
    expect(async () => await controller.createUser(newUserDto)).rejects.toThrowError(ConflictException);

    expect(checkUserUsecaseProxy.byCode).toBeCalledWith(newUserDto.code, newUserDto.companyId);
  });
  ```

<참고 자료>

- [Jest로 Error 검증시 catch 보다는 expect](https://jojoldu.tistory.com/656)
